Workbook

Sheet Tổng quan
A1: BỘ TEST CASE – KEEP FIGHTING AND EARNING
A3: Dự án | B3: Keep Fighting And Earning (2D Roguelike / Dungeon Crawler)
A4: Engine | B4: Godot Engine 4.7.x, GDScript, GL Compatibility
A5: Phạm vi | B5: Kiểm thử chức năng, biên, tiêu cực và giao diện (thủ công)
A6: Nguồn | B6: Đọc từ README.md và toàn bộ script .gd trong repo
A7: Cách dùng | B7: Cập nhật cột 'Kết quả thực tế', 'Trạng thái' ở sheet Test Case; bảng dưới tự thống kê
A9: Module | B9: Tổng | C9: Đạt | D9: Không đạt | E9: Bị chặn | F9: Chưa chạy | G9: % Đạt | H9: % Đã chạy
A10: Menu chính | B10: =COUNTIF('Test Case'!$B$2:$B$184,A10) -> 4 | C10: =COUNTIFS('Test Case'!$B$2:$B$184,$A10,'Test Case'!$L$2:$L$184,"Đạt") -> 0 | D10: =COUNTIFS('Test Case'!$B$2:$B$184,$A10,'Test Case'!$L$2:$L$184,"Không đạt") -> 0 | E10: =COUNTIFS('Test Case'!$B$2:$B$184,$A10,'Test Case'!$L$2:$L$184,"Bị chặn") -> 0 | F10: =COUNTIFS('Test Case'!$B$2:$B$184,$A10,'Test Case'!$L$2:$L$184,"Chưa chạy") -> 4 | G10: =IF(B10=0,0,C10/B10) -> 0 | H10: =IF(B10=0,0,(B10-F10)/B10) -> 0
A11: Chọn nhân vật | B11: =COUNTIF('Test Case'!$B$2:$B$184,A11) -> 7 | C11: =COUNTIFS('Test Case'!$B$2:$B$184,$A11,'Test Case'!$L$2:$L$184,"Đạt") -> 0 | D11: =COUNTIFS('Test Case'!$B$2:$B$184,$A11,'Test Case'!$L$2:$L$184,"Không đạt") -> 0 | E11: =COUNTIFS('Test Case'!$B$2:$B$184,$A11,'Test Case'!$L$2:$L$184,"Bị chặn") -> 0 | F11: =COUNTIFS('Test Case'!$B$2:$B$184,$A11,'Test Case'!$L$2:$L$184,"Chưa chạy") -> 7 | G11: =IF(B11=0,0,C11/B11) -> 0 | H11: =IF(B11=0,0,(B11-F11)/B11) -> 0
A12: Pause Menu | B12: =COUNTIF('Test Case'!$B$2:$B$184,A12) -> 8 | C12: =COUNTIFS('Test Case'!$B$2:$B$184,$A12,'Test Case'!$L$2:$L$184,"Đạt") -> 0 | D12: =COUNTIFS('Test Case'!$B$2:$B$184,$A12,'Test Case'!$L$2:$L$184,"Không đạt") -> 0 | E12: =COUNTIFS('Test Case'!$B$2:$B$184,$A12,'Test Case'!$L$2:$L$184,"Bị chặn") -> 0 | F12: =COUNTIFS('Test Case'!$B$2:$B$184,$A12,'Test Case'!$L$2:$L$184,"Chưa chạy") -> 8 | G12: =IF(B12=0,0,C12/B12) -> 0 | H12: =IF(B12=0,0,(B12-F12)/B12) -> 0
A13: Game Over | B13: =COUNTIF('Test Case'!$B$2:$B$184,A13) -> 5 | C13: =COUNTIFS('Test Case'!$B$2:$B$184,$A13,'Test Case'!$L$2:$L$184,"Đạt") -> 0 | D13: =COUNTIFS('Test Case'!$B$2:$B$184,$A13,'Test Case'!$L$2:$L$184,"Không đạt") -> 0 | E13: =COUNTIFS('Test Case'!$B$2:$B$184,$A13,'Test Case'!$L$2:$L$184,"Bị chặn") -> 0 | F13: =COUNTIFS('Test Case'!$B$2:$B$184,$A13,'Test Case'!$L$2:$L$184,"Chưa chạy") -> 5 | G13: =IF(B13=0,0,C13/B13) -> 0 | H13: =IF(B13=0,0,(B13-F13)/B13) -> 0
A14: Di chuyển & điều khiển | B14: =COUNTIF('Test Case'!$B$2:$B$184,A14) -> 7 | C14: =COUNTIFS('Test Case'!$B$2:$B$184,$A14,'Test Case'!$L$2:$L$184,"Đạt") -> 0 | D14: =COUNTIFS('Test Case'!$B$2:$B$184,$A14,'Test Case'!$L$2:$L$184,"Không đạt") -> 0 | E14: =COUNTIFS('Test Case'!$B$2:$B$184,$A14,'Test Case'!$L$2:$L$184,"Bị chặn") -> 0 | F14: =COUNTIFS('Test Case'!$B$2:$B$184,$A14,'Test Case'!$L$2:$L$184,"Chưa chạy") -> 7 | G14: =IF(B14=0,0,C14/B14) -> 0 | H14: =IF(B14=0,0,(B14-F14)/B14) -> 0
A15: Máu / Giáp / Bất tử | B15: =COUNTIF('Test Case'!$B$2:$B$184,A15) -> 13 | C15: =COUNTIFS('Test Case'!$B$2:$B$184,$A15,'Test Case'!$L$2:$L$184,"Đạt") -> 0 | D15: =COUNTIFS('Test Case'!$B$2:$B$184,$A15,'Test Case'!$L$2:$L$184,"Không đạt") -> 0 | E15: =COUNTIFS('Test Case'!$B$2:$B$184,$A15,'Test Case'!$L$2:$L$184,"Bị chặn") -> 0 | F15: =COUNTIFS('Test Case'!$B$2:$B$184,$A15,'Test Case'!$L$2:$L$184,"Chưa chạy") -> 13 | G15: =IF(B15=0,0,C15/B15) -> 0 | H15: =IF(B15=0,0,(B15-F15)/B15) -> 0
A16: Pyrois | B16: =COUNTIF('Test Case'!$B$2:$B$184,A16) -> 10 | C16: =COUNTIFS('Test Case'!$B$2:$B$184,$A16,'Test Case'!$L$2:$L$184,"Đạt") -> 0 | D16: =COUNTIFS('Test Case'!$B$2:$B$184,$A16,'Test Case'!$L$2:$L$184,"Không đạt") -> 0 | E16: =COUNTIFS('Test Case'!$B$2:$B$184,$A16,'Test Case'!$L$2:$L$184,"Bị chặn") -> 0 | F16: =COUNTIFS('Test Case'!$B$2:$B$184,$A16,'Test Case'!$L$2:$L$184,"Chưa chạy") -> 10 | G16: =IF(B16=0,0,C16/B16) -> 0 | H16: =IF(B16=0,0,(B16-F16)/B16) -> 0
A17: Olaf | B17: =COUNTIF('Test Case'!$B$2:$B$184,A17) -> 6 | C17: =COUNTIFS('Test Case'!$B$2:$B$184,$A17,'Test Case'!$L$2:$L$184,"Đạt") -> 0 | D17: =COUNTIFS('Test Case'!$B$2:$B$184,$A17,'Test Case'!$L$2:$L$184,"Không đạt") -> 0 | E17: =COUNTIFS('Test Case'!$B$2:$B$184,$A17,'Test Case'!$L$2:$L$184,"Bị chặn") -> 0 | F17: =COUNTIFS('Test Case'!$B$2:$B$184,$A17,'Test Case'!$L$2:$L$184,"Chưa chạy") -> 6 | G17: =IF(B17=0,0,C17/B17) -> 0 | H17: =IF(B17=0,0,(B17-F17)/B17) -> 0
A18: Miya | B18: =COUNTIF('Test Case'!$B$2:$B$184,A18) -> 10 | C18: =COUNTIFS('Test Case'!$B$2:$B$184,$A18,'Test Case'!$L$2:$L$184,"Đạt") -> 0 | D18: =COUNTIFS('Test Case'!$B$2:$B$184,$A18,'Test Case'!$L$2:$L$184,"Không đạt") -> 0 | E18: =COUNTIFS('Test Case'!$B$2:$B$184,$A18,'Test Case'!$L$2:$L$184,"Bị chặn") -> 0 | F18: =COUNTIFS('Test Case'!$B$2:$B$184,$A18,'Test Case'!$L$2:$L$184,"Chưa chạy") -> 10 | G18: =IF(B18=0,0,C18/B18) -> 0 | H18: =IF(B18=0,0,(B18-F18)/B18) -> 0
A19: Charlotte | B19: =COUNTIF('Test Case'!$B$2:$B$184,A19) -> 8 | C19: =COUNTIFS('Test Case'!$B$2:$B$184,$A19,'Test Case'!$L$2:$L$184,"Đạt") -> 0 | D19: =COUNTIFS('Test Case'!$B$2:$B$184,$A19,'Test Case'!$L$2:$L$184,"Không đạt") -> 0 | E19: =COUNTIFS('Test Case'!$B$2:$B$184,$A19,'Test Case'!$L$2:$L$184,"Bị chặn") -> 0 | F19: =COUNTIFS('Test Case'!$B$2:$B$184,$A19,'Test Case'!$L$2:$L$184,"Chưa chạy") -> 8 | G19: =IF(B19=0,0,C19/B19) -> 0 | H19: =IF(B19=0,0,(B19-F19)/B19) -> 0
A20: Vật phẩm | B20: =COUNTIF('Test Case'!$B$2:$B$184,A20) -> 11 | C20: =COUNTIFS('Test Case'!$B$2:$B$184,$A20,'Test Case'!$L$2:$L$184,"Đạt") -> 0 | D20: =COUNTIFS('Test Case'!$B$2:$B$184,$A20,'Test Case'!$L$2:$L$184,"Không đạt") -> 0 | E20: =COUNTIFS('Test Case'!$B$2:$B$184,$A20,'Test Case'!$L$2:$L$184,"Bị chặn") -> 0 | F20: =COUNTIFS('Test Case'!$B$2:$B$184,$A20,'Test Case'!$L$2:$L$184,"Chưa chạy") -> 11 | G20: =IF(B20=0,0,C20/B20) -> 0 | H20: =IF(B20=0,0,(B20-F20)/B20) -> 0
A21: Túi đồ & trang bị | B21: =COUNTIF('Test Case'!$B$2:$B$184,A21) -> 12 | C21: =COUNTIFS('Test Case'!$B$2:$B$184,$A21,'Test Case'!$L$2:$L$184,"Đạt") -> 0 | D21: =COUNTIFS('Test Case'!$B$2:$B$184,$A21,'Test Case'!$L$2:$L$184,"Không đạt") -> 0 | E21: =COUNTIFS('Test Case'!$B$2:$B$184,$A21,'Test Case'!$L$2:$L$184,"Bị chặn") -> 0 | F21: =COUNTIFS('Test Case'!$B$2:$B$184,$A21,'Test Case'!$L$2:$L$184,"Chưa chạy") -> 12 | G21: =IF(B21=0,0,C21/B21) -> 0 | H21: =IF(B21=0,0,(B21-F21)/B21) -> 0
... A31: Hệ thống & môi trường | B31: =COUNTIF('Test Case'!$B$2:$B$184,A31) -> 6 | C31: =COUNTIFS('Test Case'!$B$2:$B$184,$A31,'Test Case'!$L$2:$L$184,"Đạt") -> 0 | D31: =COUNTIFS('Test Case'!$B$2:$B$184,$A31,'Test Case'!$L$2:$L$184,"Không đạt") -> 0 | E31: =COUNTIFS('Test Case'!$B$2:$B$184,$A31,'Test Case'!$L$2:$L$184,"Bị chặn") -> 0 | F31: =COUNTIFS('Test Case'!$B$2:$B$184,$A31,'Test Case'!$L$2:$L$184,"Chưa chạy") -> 6 | G31: =IF(B31=0,0,C31/B31) -> 0 | H31: =IF(B31=0,0,(B31-F31)/B31) -> 0
A32: TỔNG CỘNG | B32: =SUM(B10:B31) -> 183 | C32: =SUM(C10:C31) -> 0 | D32: =SUM(D10:D31) -> 0 | E32: =SUM(E10:E31) -> 0 | F32: =SUM(F10:F31) -> 183 | G32: =IF(B32=0,0,C32/B32) -> 0 | H32: =IF(B32=0,0,(B32-F32)/B32) -> 0

Sheet Test Case
A1: ID | B1: Module | C1: Chức năng | D1: Tiêu đề test case | E1: Điều kiện tiên quyết | F1: Các bước thực hiện | G1: Dữ liệu test | H1: Kết quả mong đợi | I1: Loại | J1: Ưu tiên | K1: Kết quả thực tế | L1: Trạng thái | M1: Người test | N1: Ngày test | O1: Ghi chú
A2: TC-MN-01 | B2: Menu chính | C2: Hiển thị | D2: Main Menu hiển thị khi khởi chạy game | E2: Đã import dự án vào Godot | F2: 1. Nhấn F5 để chạy game | G2: - | H2: Hiển thị Main Menu có nút Start và Exit; không có lỗi trong Output | I2: Chức năng | J2: Cao | L2: Chưa chạy | O2: README ghi có thêm nút Options nhưng script main_menu.gd chỉ xử lý Start và Exit
A3: TC-MN-02 | B3: Menu chính | C3: Start | D3: Nhấn Start chuyển sang màn Chọn nhân vật | E3: Đang ở Main Menu | F3: 1. Nhấn nút Start | G3: - | H3: Chuyển sang scene CharacterSelect, hiển thị 4 nút nhân vật | I3: Chức năng | J3: Cao | L3: Chưa chạy
A4: TC-MN-03 | B4: Menu chính | C4: Exit | D4: Nhấn Exit thoát game | E4: Đang ở Main Menu | F4: 1. Nhấn nút Exit | G4: - | H4: Cửa sổ game đóng, tiến trình dừng | I4: Chức năng | J4: Cao | L4: Chưa chạy
A5: TC-MN-04 | B5: Menu chính | C5: Start | D5: Nhấn Start nhiều lần liên tiếp | E5: Đang ở Main Menu | F5: 1. Nhấn nhanh nút Start 5 lần | G5: - | H5: Chỉ chuyển scene một lần, không lỗi, không tạo scene trùng | I5: Tiêu cực | J5: Trung bình | L5: Chưa chạy | O5: Script dùng button_down nên kích hoạt ngay khi nhấn xuống
A6: TC-CS-01 | B6: Chọn nhân vật | C6: Chọn nhân vật | D6: Chọn Pyrois vào game thành công | E6: Đang ở màn Chọn nhân vật | F6: 1. Nhấn nút nhân vật 1 (Pyrois) 2. Quan sát màn chơi và HUD | G6: Nhân vật: Pyrois | H6: Vào world.tscn, nhân vật Pyrois xuất hiện ở phòng xuất phát; HUD hiển thị 4 tim và 4 giáp (chưa trang bị) | I6: Chức năng | J6: Cao | L6: Chưa chạy | O6: README ghi Pyrois 'khởi điểm 5 máu' nhưng code: hp = max_hp = base_max_hp (4)
A7: TC-CS-02 | B7: Chọn nhân vật | C7: Chọn nhân vật | D7: Chọn Olaf vào game thành công | E7: Đang ở màn Chọn nhân vật | F7: 1. Nhấn nút nhân vật 2 (Olaf) 2. Quan sát màn chơi và HUD | G7: Nhân vật: Olaf | H7: Vào world.tscn, nhân vật Olaf xuất hiện ở phòng xuất phát; HUD hiển thị 6 tim và 1 giáp (chưa trang bị) | I7: Chức năng | J7: Cao | L7: Chưa chạy
A8: TC-CS-03 | B8: Chọn nhân vật | C8: Chọn nhân vật | D8: Chọn Miya vào game thành công | E8: Đang ở màn Chọn nhân vật | F8: 1. Nhấn nút nhân vật 3 (Miya) 2. Quan sát màn chơi và HUD | G8: Nhân vật: Miya | H8: Vào world.tscn, nhân vật Miya xuất hiện ở phòng xuất phát; HUD hiển thị 4 tim và 1 giáp (chưa trang bị) | I8: Chức năng | J8: Cao | L8: Chưa chạy
A9: TC-CS-04 | B9: Chọn nhân vật | C9: Chọn nhân vật | D9: Chọn Charlotte vào game thành công | E9: Đang ở màn Chọn nhân vật | F9: 1. Nhấn nút nhân vật 4 (Charlotte) 2. Quan sát màn chơi và HUD | G9: Nhân vật: Charlotte | H9: Vào world.tscn, nhân vật Charlotte xuất hiện ở phòng xuất phát; HUD hiển thị 5 tim và 0 giáp (chưa trang bị) | I9: Chức năng | J9: Cao | L9: Chưa chạy
A10: TC-CS-05 | B10: Chọn nhân vật | C10: Chọn nhân vật | D10: Nhân vật đã chọn được giữ khi Retry | E10: Đã chơi và chết với Olaf | F10: 1. Ở màn Game Over nhấn Retry 2. Chọn Miya 3. Quan sát nhân vật trong game | G10: - | H10: Vào game với Miya, không bị dùng lại Olaf | I10: Chức năng | J10: Trung bình | L10: Chưa chạy
A11: TC-CS-06 | B11: Chọn nhân vật | C11: Chọn nhân vật | D11: Nhân vật cũ không bị giữ khi chọn lại | E11: Đã chơi 1 ván với Pyrois rồi Retry | F11: 1. Chọn Charlotte 2. Vào game | G11: - | H11: Nhân vật là Charlotte (GameManager cập nhật đúng) | I11: Chức năng | J11: Trung bình | L11: Chưa chạy
A12: TC-CS-07 | B12: Chọn nhân vật | C12: Chọn nhân vật | D12: Nhấn nhanh 2 nút nhân vật liên tiếp | E12: Đang ở màn Chọn nhân vật | F12: 1. Nhấn nút Char_1 rồi Char_4 thật nhanh | G12: - | H12: Game vào world một lần, không lỗi hoặc crash | I12: Tiêu cực | J12: Thấp | L12: Chưa chạy
A13: TC-PA-01 | B13: Pause Menu | C13: Pause | D13: ESC mở Pause Menu | E13: Đang trong màn chơi | F13: 1. Nhấn ESC | G13: - | H13: Pause Menu hiện, game dừng (quái, bẫy, đạn đứng yên) | I13: Chức năng | J13: Cao | L13: Chưa chạy
A14: TC-PA-02 | B14: Pause Menu | C14: Pause | D14: ESC lần 2 tiếp tục game | E14: Pause Menu đang mở | F14: 1. Nhấn ESC lần nữa | G14: - | H14: Menu ẩn, game chạy tiếp | I14: Chức năng | J14: Cao | L14: Chưa chạy
A15: TC-PA-03 | B15: Pause Menu | C15: Pause | D15: Nút Resume tiếp tục game | E15: Pause Menu đang mở | F15: 1. Nhấn Resume | G15: - | H15: Menu ẩn, game chạy tiếp | I15: Chức năng | J15: Cao | L15: Chưa chạy
A16: TC-PA-04 | B16: Pause Menu | C16: Pause | D16: Nút Restart tải lại màn chơi | E16: Đang chơi tầng 2 hoặc đã nhặt đồ | F16: 1. Mở Pause, nhấn Restart | G16: - | H16: Scene world tải lại, tầng về giá trị khởi đầu, túi đồ và chỉ số được khởi tạo lại; vẫn dùng nhân vật đã chọn | I16: Chức năng | J16: Cao | L16: Chưa chạy | O16: Restart dùng reload_current_scene nên không quay về màn Chọn nhân vật
A17: TC-PA-05 | B17: Pause Menu | C17: Pause | D17: Nút Exit thoát game | E17: Pause Menu đang mở | F17: 1. Nhấn Exit | G17: - | H17: Game đóng | I17: Chức năng | J17: Trung bình | L17: Chưa chạy
A18: TC-PA-06 | B18: Pause Menu | C18: Pause | D18: Không bấm được hành động khi game tạm dừng | E18: Pause Menu đang mở | F18: 1. Click chuột, nhấn WASD, Q, 1-9 | G18: - | H18: Nhân vật không di chuyển/tấn công/dùng vật phẩm khi đang pause | I18: Tiêu cực | J18: Trung bình | L18: Chưa chạy
A19: TC-PA-07 | B19: Pause Menu | C19: Pause | D19: ESC không mở Pause khi đang Game Over | E19: Nhân vật vừa chết, Game Over Menu đang hiện | F19: 1. Nhấn ESC | G19: - | H19: Pause Menu không hiện (bị chặn bởi kiểm tra game_over_menu) | I19: Tiêu cực | J19: Trung bình | L19: Chưa chạy
A20: TC-PA-08 | B20: Pause Menu | C20: Pause | D20: Timer tạm dừng cùng game | E20: Cooldown kỹ năng Q đang đếm | F20: 1. Nhấn Q 2. Ngay lập tức pause 10 giây 3. Resume 4. Quan sát cooldown | G20: - | H20: Cooldown không giảm trong lúc pause | I20: Biên | J20: Thấp | L20: Chưa chạy
A21: TC-GO-01 | B21: Game Over | C21: Game Over | D21: Hiện Game Over khi hết máu | E21: Nhân vật còn 1 máu, giáp = 0 | F21: 1. Để quái đánh trúng nhân vật 2. Chờ 2 giây sau hoạt ảnh chết | G21: - | H21: Phát hoạt ảnh death; sau 2 giây hiện Game Over Menu và game tạm dừng | I21: Chức năng | J21: Cao | L21: Chưa chạy
A22: TC-GO-02 | B22: Game Over | C22: Game Over | D22: Nút Retry quay về Chọn nhân vật | E22: Game Over Menu đang hiện | F22: 1. Nhấn Retry | G22: - | H22: Game bỏ pause và chuyển về màn Chọn nhân vật | I22: Chức năng | J22: Cao | L22: Chưa chạy
A23: TC-GO-03 | B23: Game Over | C23: Game Over | D23: Nút Exit thoát game | E23: Game Over Menu đang hiện | F23: 1. Nhấn Exit | G23: - | H23: Game đóng | I23: Chức năng | J23: Trung bình | L23: Chưa chạy
A24: TC-GO-04 | B24: Game Over | C24: Game Over | D24: Nhân vật chết không còn nhận thêm sát thương | E24: Nhân vật vừa chết | F24: 1. Để quái/bẫy đánh tiếp trong 2 giây chờ | G24: - | H24: Không phát sinh thêm lỗi; Game Over chỉ hiện một lần | I24: Tiêu cực | J24: Trung bình | L24: Chưa chạy
A25: TC-GO-05 | B25: Game Over | C25: Game Over | D25: Không điều khiển được khi đã chết | E25: Nhân vật vừa chết (trong 2 giây chờ) | F25: 1. Nhấn WASD, Q, chuột trái, phím 1-9 | G25: - | H25: Nhân vật không phản hồi (is_dead = true) | I25: Tiêu cực | J25: Trung bình | L25: Chưa chạy
A26: TC-MV-01 | B26: Di chuyển & điều khiển | C26: Di chuyển | D26: Di chuyển 4 hướng W/A/S/D | E26: Đang trong màn chơi, Pyrois | F26: 1. Nhấn lần lượt W, A, S, D | G26: - | H26: Nhân vật di chuyển lên, trái, xuống, phải; phát hoạt ảnh walk; dừng thì phát idle | I26: Chức năng | J26: Cao | L26: Chưa chạy
A27: TC-MV-02 | B27: Di chuyển & điều khiển | C27: Di chuyển | D27: Di chuyển chéo không nhanh hơn | E27: Pyrois, tốc độ 150 | F27: 1. Giữ W+D cùng lúc và đo quãng đường trong 2 giây 2. So sánh với chỉ giữ D | G27: - | H27: Tốc độ chéo bằng tốc độ thẳng (vector chuẩn hóa) | I27: Biên | J27: Trung bình | L27: Chưa chạy
A28: TC-MV-03 | B28: Di chuyển & điều khiển | C28: Di chuyển | D28: Nhấn hai phím ngược chiều | E28: - | F28: 1. Giữ A và D cùng lúc | G28: - | H28: Nhân vật đứng yên, phát idle | I28: Biên | J28: Thấp | L28: Chưa chạy
... A58: TC-OL-03 | B58: Olaf | C58: Kỹ năng Q | D58: Hết buff sát thương trở về bình thường | E58: - | F58: 1. Nhấn Q 2. Chờ 5 giây 3. Chém quái | G58: - | H58: Sát thương về 2; không bị cộng dồn hay thấp hơn ban đầu | I58: Biên | J58: Cao | L58: Chưa chạy
A59: TC-OL-04 | B59: Olaf | C59: Kỹ năng Q | D59: Buff cộng đúng khi có vũ khí | E59: Olaf đã trang bị Kiếm sắt (+1) | F59: 1. Nhấn Q 2. Chém quái | G59: base 2, vũ khí +1 | H59: Sát thương trong buff = (2 + 2) + 1 = 5; hết buff về 2 + 1 = 3 | I59: Biên | J59: Trung bình | L59: Chưa chạy | O59: Kiểm tra README ghi 'nhân đôi sát thương của đòn đánh'; vũ khí không được nhân đôi
A60: TC-OL-05 | B60: Olaf | C60: Kỹ năng Q | D60: Cooldown Q 5 giây | E60: - | F60: 1. Nhấn Q 2. Nhấn Q lần nữa sau 3 giây | G60: Cooldown 5.0s | H60: Lần 2 không kích hoạt | I60: Biên | J60: Trung bình | L60: Chưa chạy
A61: TC-OL-06 | B61: Olaf | C61: Kỹ năng Q | D61: Chết trong lúc buff | E61: Olaf đang buff | F61: 1. Để quái đánh chết Olaf trong lúc buff | G61: - | H61: Không phát sinh lỗi script; Game Over hiện bình thường | I61: Tiêu cực | J61: Thấp | L61: Chưa chạy
A62: TC-MI-01 | B62: Miya | C62: Chỉ số | D62: Chỉ số khởi đầu của Miya | E62: Chọn Miya | F62: 1. Kiểm tra HUD, tốc độ, sát thương | G62: - | H62: Tốc độ 180, Máu 4, Giáp 1, Sát thương 2 | I62: Chức năng | J62: Cao | L62: Chưa chạy
A63: TC-MI-02 | B63: Miya | C63: Tấn công | D63: Bắn tên theo hướng chuột | E63: Miya | F63: 1. Hướng chuột sang phải 2. Nhấn chuột trái | G63: - | H63: Mũi tên xuất hiện cách nhân vật 16 px, bay thẳng về phía chuột, góc quay đúng hướng | I63: Chức năng | J63: Cao | L63: Chưa chạy
A64: TC-MI-03 | B64: Miya | C64: Tấn công | D64: Sát thương mũi tên bằng tổng sát thương | E64: Miya có Kiếm tai ương (+8) | F64: 1. Bắn trúng quái | G64: 2 + 8 | H64: Quái nhận 10 sát thương | I64: Chức năng | J64: Trung bình | L64: Chưa chạy
A65: TC-MI-04 | B65: Miya | C65: Tấn công | D65: Mũi tên tự hủy sau 2 giây | E65: Bắn vào khoảng trống rộng | F65: 1. Bắn tên ra xa | G65: Tốc độ 300, sống 2s | H65: Mũi tên biến mất sau 2 giây | I65: Biên | J65: Trung bình | L65: Chưa chạy
A66: TC-MI-05 | B66: Miya | C66: Tấn công | D66: Mũi tên biến mất khi trúng tường | E66: - | F66: 1. Bắn vào tường | G66: - | H66: Mũi tên biến mất ngay khi chạm tường | I66: Chức năng | J66: Trung bình | L66: Chưa chạy
A67: TC-MI-06 | B67: Miya | C67: Tấn công | D67: Mũi tên không gây sát thương cho Miya | E67: - | F67: 1. Bắn sát tường để tên bắn lên bản thân | G67: - | H67: Mũi tên bỏ qua người chơi | I67: Tiêu cực | J67: Thấp | L67: Chưa chạy
A68: TC-MI-07 | B68: Miya | C68: Kỹ năng Q | D68: Ném bom tới vị trí chuột | E68: Miya | F68: 1. Đặt chuột ở vị trí A 2. Nhấn Q | G68: Sát thương bom = 3 x tổng sát thương | H68: Bom bay tới A trong 0.4s, chờ 0.5s rồi nổ; quái trong vùng nổ nhận 6 sát thương | I68: Chức năng | J68: Cao | L68: Chưa chạy
A69: TC-MI-08 | B69: Miya | C69: Kỹ năng Q | D69: Bom không gây sát thương cho người chơi | E69: Miya đứng trong vùng nổ | F69: 1. Ném bom dưới chân | G69: - | H69: Miya không mất máu/giáp | I69: Tiêu cực | J69: Cao | L69: Chưa chạy
...

Sheet Điểm cần xác minh
A1: STT | B1: Vấn đề phát hiện khi đọc mã nguồn | C1: Chi tiết | D1: File liên quan | E1: Mức độ
A2: 1 | B2: README ghi 10 phòng, code mặc định 16 | C2: dungeon_generator.gd khai báo num_rooms = 16 và world.tscn không ghi đè. | D2: Scene/Map/dungeon_generator.gd | E2: Trung bình
A3: 2 | B3: Boss Kitsune không tồn tại trong repo | C3: Không có thư mục Boss/Kitsune. Tầng chẵn sinh Orc Rider nhưng log in ra 'Kitsune xuất hiện'. | D3: dungeon_generator.gd, Scene/Enemies/Boss | E3: Cao
A4: 3 | B4: Blood Monster không tồn tại | C4: README liệt kê Blood Monster nhưng không có file và không có trong enemy_scenes. | D4: dungeon_generator.gd, README.md | E4: Trung bình
A5: 4 | B5: Mô tả Kiếm tai ương không khớp dữ liệu | C5: Mô tả '+1 DMG +1 Giáp' nhưng damage = 8, armor = 1. | D5: Scene/Items/mystic_sword.tres | E5: Cao
A6: 5 | B6: Bình máu lớn thiếu tên | C6: big_health_potion.tres không đặt item_name, tooltip sẽ hiện tên mặc định 'Vật phẩm mới'. | D6: Scene/Items/big_health_potion.tres | E6: Thấp
A7: 6 | B7: Code thử nghiệm còn trong player.gd | C7: _ready() tự thêm Bình máu nhỏ, Giáp cốt, Kiếm tai ương vào túi (chú thích 'Test thử'). | D7: Scene/Character/Player 1_Pyrois/player.gd | E7: Trung bình
A8: 7 | B8: Vật phẩm túi ô 10-16 khó sử dụng | C8: Túi 16 ô nhưng hotbar chỉ 9 ô và phím 1-9; không có UI cho ô 10-16 trong repo. | D8: InventoryManager.gd, GameUI.gd | E8: Trung bình
A9: 8 | B9: Chưa có UI tháo trang bị | C9: unequip_item() có sẵn nhưng không có ô trang bị gọi tới; README nói click ô để tháo. | D9: InventoryManager.gd, GameUI.gd | E9: Trung bình
A10: 9 | B10: Pyrois 'khởi điểm 5 máu' theo README | C10: Code: base_max_hp = 4 và hp = max_hp = 4 khi vào game. | D10: Player 1_Pyrois/player.gd | E10: Thấp
A11: 10 | B11: Quái Skeleton/Vampire không có hàm rớt đồ | C11: README nói quái thường 30% rớt đồ; chỉ Orc và Armored Orc có drop_loot. | D11: skeleton.gd, vampire.gd, orc.gd | E11: Trung bình
A12: 11 | B12: PLAYER_SCENE trỏ tới file .gd | C12: preload('.../player.gd').instantiate() sẽ lỗi nếu GameManager không có nhân vật; hiện chưa xảy ra nhờ GameManager đặt mặc định. | D12: dungeon_generator.gd | E12: Thấp
A13: 12 | B13: Retry và Restart đưa tới nơi khác nhau | C13: Game Over → Retry về màn Chọn nhân vật; Pause → Restart tải lại world, giữ nhân vật. | D13: game_over_menu.gd, pause_menu.gd | E13: Thấp
A14: 13 | B14: Buff Olaf cộng theo base_damage | C14: Buff cộng thêm base_damage nên vũ khí không được nhân đôi; cần xác nhận với thiết kế. | D14: Player 2_Olaf/player_2.gd | E14: Thấp
